Workbook

Sheet Dashboard
B2: Portfolio Dashboard
B4: Net Asset Value | D4: Total Return | F4: Sharpe Ratio (ann.) | H4: Max Drawdown
B5: =Equity_Curve!D262 | D5: =Equity_Curve!F262 | F5: =AVERAGE(Equity_Curve!E3:E262)/STDEV(Equity_Curve!E3:E262)*SQRT(252) | H5: =MIN(Equity_Curve!G2:G262)
B8: Cash | D8: Invested Value
B9: =Equity_Curve!B262 | D9: =Equity_Curve!C262

Sheet Trade_Log
A1: Date | B1: Symbol | C1: Company | D1: SecType | E1: Currency | F1: Side | G1: Size | H1: Price | I1: Commission | J1: NetAmount | K1: RealizedPnL | L1: Exchange | M1: OrderType
A2: 2025-07-08 | B2: SBET | C2: SHARPLINK INC | D2: STK | E2: USD | F2: BUY | G2: 3 | H2: 15.72 | I2: 0.35093825 | J2: 47.16 | K2: 0 | L2: DARK | M2: MARKET
A3: 2025-07-08 | B3: GDX | C3: VANECK GOLD MINERS ETF | D3: STK | E3: USD | F3: BUY | G3: 5 | H3: 50.445 | I3: 0.35139225 | J3: 252.225 | K3: 0 | L3: IBKRATS | M3: MARKET
A4: 2025-07-08 | B4: SIL | C4: GLOBAL X SILVER MINERS ETF | D4: STK | E4: USD | F4: BUY | G4: 3 | H4: 47.505 | I4: 0.35093825 | J4: 142.515 | K4: 0 | L4: DARK | M4: MARKET
A5: 2025-07-08 | B5: COPX | C5: GLOBAL X COPPER MINERS ETF | D5: STK | E5: USD | F5: BUY | G5: 5 | H5: 45.83 | I5: 0.35139225 | J5: 229.15 | K5: 0 | L5: IBKRATS | M5: LIMIT
A6: 2025-07-11 | B6: SBET | C6: SHARPLINK INC | D6: STK | E6: USD | F6: SELL | G6: 3 | H6: 21.115 | I6: 0.35143625 | J6: 63.345 | K6: 15.482626 | L6: DARK | M6: MARKET
A7: 2025-07-14 | B7: IREN | C7: IREN LTD | D7: STK | E7: USD | F7: BUY | G7: 7 | H7: 18.4391 | I7: 0.35184625 | J7: 129.0737 | K7: 0 | L7: DARK | M7: MARKET
A8: 2025-07-14 | B8: CLSK | C8: CLEANSPARK INC | D8: STK | E8: USD | F8: BUY | G8: 6 | H8: 13.54 | I8: 0.34378925 | J8: 81.24 | K8: 0 | L8: ISLAND | M8: LIMIT
A9: 2025-07-14 | B9: OKLO | C9: OKLO INC | D9: STK | E9: USD | F9: BUY | G9: 2 | H9: 57.76 | I9: 0.34830125 | J9: 115.52 | K9: 0 | L9: NYSE | M9: LIMIT
A10: 2025-07-14 | B10: ARGT | C10: GLOBAL X MSCI ARGENTINA ETF | D10: STK | E10: USD | F10: BUY | G10: 3 | H10: 79.89 | I10: 0.35093825 | J10: 239.67 | K10: 0 | L10: IBKRATS | M10: MARKET
A11: 2025-07-16 | B11: SIL | C11: GLOBAL X SILVER MINERS ETF | D11: STK | E11: USD | F11: BUY | G11: 4 | H11: 48.81 | I11: 0.35114525 | J11: 195.24 | K11: 0 | L11: DRCTEDGE | M11: LIMIT
A12: 2025-07-22 | B12: BIDU | C12: BAIDU INC - SPON ADR | D12: STK | E12: USD | F12: BUY | G12: 2 | H12: 92.64 | I12: 0.34810125 | J12: 185.28 | K12: 0 | L12: ISLAND | M12: LIMIT
A13: 2025-07-23 | B13: ARGT | C13: GLOBAL X MSCI ARGENTINA ETF | D13: STK | E13: USD | F13: BUY | G13: 2 | H13: 81.375 | I13: 0.35071125 | J13: 162.75 | K13: 0 | L13: DARK | M13: LIMIT
... A138: 2026-02-18 | B138: EWZ | C138: ISHARES MSCI BRAZIL ETF | D138: STK | E138: USD | F138: BUY | G138: 10 | H138: 38.12 | I138: 0.35225725 | J138: 381.2 | K138: 0 | L138: IBKRATS | M138: LIMIT
A139: 2026-02-19 | B139: SOXS | D139: STK | E139: USD | F139: BUY | G139: 250 | H139: 1.7693 | I139: 0.92564313 | J139: 442.325 | K139: 0 | L139: DARK | M139: LIMIT
A140: 2026-02-23 | B140: PPLT | C140: ABRDN PHYSICAL PLATINUM SHRS | D140: STK | E140: USD | F140: SELL | G140: 6 | H140: 193.14 | I140: 0.34302725 | J140: 1158.84 | K140: 127.39268 | L140: ARCA | M140: LIMIT
A141: 2026-02-23 | B141: PPLT | C141: ABRDN PHYSICAL PLATINUM SHRS | D141: STK | E141: USD | F141: SELL | G141: 0.5 | H141: 193.14 | I141: 0.0001975 | J141: 96.57 | K141: -22.425555 | L141: IBKR | M141: LIMIT
A142: 2026-02-24 | B142: SOXS | D142: STK | E142: USD | F142: SELL | G142: 250 | H142: 1.62 | I142: 0.97439312 | J142: 405 | K142: -39.225036 | L142: IBKRATS | M142: STOP_LIMIT
A143: 2026-03-02 | B143: BABA | C143: ALIBABA GROUP HOLDING-SP ADR | D143: STK | E143: USD | F143: SELL | G143: 4 | H143: 140.45 | I143: 0.33903725 | J143: 561.8 | K143: -97.278674 | L143: NYSE | M143: LIMIT
A144: 2026-03-02 | B144: FAZ | C144: DIREX DLY FIN BEA 3X ETF-USD | D144: STK | E144: USD | F144: BUY | G144: 10 | H144: 45.6 | I144: 0.33625725 | J144: 456 | K144: 0 | L144: ARCA | M144: LIMIT
A145: 2026-03-02 | B145: DFEN | C145: DIREX DLY AEROS & DF BL3X-UI | D145: STK | E145: USD | F145: BUY | G145: 4 | H145: 96.93 | I145: 0.35105725 | J145: 387.72 | K145: 0 | L145: IBKRATS | M145: LIMIT
A146: 2026-03-03 | B146: DFEN | C146: DIREX DLY AEROS & DF BL3X-UI | D146: STK | E146: USD | F146: SELL | G146: 4 | H146: 89.53 | I146: 0.34543725 | J146: 358.12 | K146: -30.296494 | L146: ARCA | M146: LIMIT
A147: 2026-03-03 | B147: ZROZ | C147: PIMCO 25+ YR ZERO CPN US TIF | D147: STK | E147: USD | F147: SELL | G147: 1 | H147: 66.99 | I147: 0.35065225 | J147: 66.99 | K147: -0.940204 | L147: DARK | M147: LIMIT
A148: 2026-03-03 | B148: ZROZ | C148: PIMCO 25+ YR ZERO CPN US TIF | D148: STK | E148: USD | F148: SELL | G148: 4 | H148: 66.99 | I148: 0.00158 | J148: 267.96 | K148: -2.359786 | L148: DARK | M148: LIMIT
A149: 2026-03-03 | B149: BOIL | D149: STK | E149: USD | F149: BUY | G149: 20 | H149: 18.7593 | I149: 0.35425725 | J149: 375.186 | K149: 0 | L149: DARK | M149: LIMIT
A150: 2026-03-03 | B150: EWZ | C150: ISHARES MSCI BRAZIL ETF | D150: STK | E150: USD | F150: SELL | G150: 10 | H150: 36.93 | I150: 0.35420725 | J150: 369.3 | K150: -12.606464 | L150: IBKRATS | M150: LIMIT
A151: 2026-03-03 | B151: SLV | C151: ISHARES SILVER TRUST | D151: STK | E151: USD | F151: SELL | G151: 15 | H151: 75.095 | I151: 0.35618225 | J151: 1126.425 | K151: -32.881295 | L151: DARK | M151: LIMIT
A152: 2026-03-03 | B152: GLD | C152: SPDR GOLD SHARES | D152: STK | E152: USD | F152: SELL | G152: 8 | H152: 471.31 | I152: 0.35341725 | J152: 3770.48 | K152: 315.01094 | L152: IBKRATS | M152: LIMIT
A153: 2026-03-03 | B153: CPER | C153: UNITED STATES COPPER INDEX | D153: STK | E153: USD | F153: SELL | G153: 17 | H153: 35.71 | I153: 0.32977225 | J153: 607.07 | K153: -11.295686 | L153: ARCA | M153: LIMIT
A154: 2026-03-05 | B154: SOXS | C154: DIREX DAI SEMI BE 3X ETF-USD | D154: STK | E154: USD | F154: BUY | G154: 10 | H154: 41.8293 | I154: 0.35225725 | J154: 418.293 | K154: 0 | L154: DARK | M154: LIMIT
A155: 2026-03-09 | B155: BOIL | D155: STK | E155: USD | F155: SELL | G155: 20 | H155: 18.41 | I155: 0.32215725 | J155: 368.2 | K155: -7.662414 | L155: NASDAQ | M155: LIMIT
A156: 2026-03-10 | B156: UVIX | D156: STK | E156: USD | F156: BUY | G156: 40 | H156: 7.585 | I156: 0.35825725 | J156: 303.4 | K156: 0 | L156: IBKRATS | M156: LIMIT
A157: 2026-03-10 | B157: USO | C157: UNITED STATES OIL FUND LP | D157: STK | E157: USD | F157: BUY | G157: 2 | H157: 106.188 | I157: 0.35065725 | J157: 212.376 | K157: 0 | L157: DARK | M157: MARKET
A158: 2026-03-11 | B158: CF | C158: CF INDUSTRIES HOLDINGS INC | D158: STK | E158: USD | F158: BUY | G158: 2 | H158: 119.41 | I158: 0.34425725 | J158: 238.82 | K158: 0 | L158: NYSE | M158: LIMIT
A159: 2026-03-11 | B159: NTR | C159: NUTRIEN LTD | D159: STK | E159: USD | F159: BUY | G159: 4 | H159: 78.87 | I159: 0.33825725 | J159: 315.48 | K159: 0 | L159: BATS | M159: LIMIT
A160: 2026-03-12 | B160: GLL | C160: PROSHARES ULTRASHORT GOLD | D160: STK | E160: USD | F160: BUY | G160: 20 | H160: 17.48 | I160: 0.35425725 | J160: 349.6 | K160: 0 | L160: IBKRATS | M160: LIMIT
A161: 2026-03-13 | B161: USO | C161: UNITED STATES OIL FUND LP | D161: STK | E161: USD | F161: SELL | G161: 2 | H161: 119.185 | I161: 0.35104725 | J161: 238.37 | K161: 25.292296 | L161: DARK | M161: LIMIT
A162: 2026-03-13 | B162: CF | C162: CF INDUSTRIES HOLDINGS INC | D162: STK | E162: USD | F162: SELL | G162: 2 | H162: 129.76 | I162: 0.34464725 | J162: 259.52 | K162: 20.011096 | L162: NYSE | M162: LIMIT
A163: 2026-03-13 | B163: GLL | C163: PROSHARES ULTRASHORT GOLD | D163: STK | E163: USD | F163: SELL | G163: 20 | H163: 17.875 | I163: 0.35815725 | J163: 357.5 | K163: 7.187586 | L163: IBKRATS | M163: LIMIT
A164: 2026-03-13 | B164: SOXS | C164: DIREX DAI SEMI BE 3X ETF-USD | D164: STK | E164: USD | F164: SELL | G164: 10 | H164: 41.4 | I164: 0.35420725 | J164: 414 | K164: -4.999464 | L164: IBKRATS | M164: LIMIT
...

Sheet Market_Data
A1: Date | B1: CGNX | C1: COPX | D1: DRAM | E1: DTC | F1: EMAAR | G1: EMIRATESN | H1: FPS | I1: GDXJ | J1: HOOD | K1: ONDS | L1: RBRK | M1: RDDT | N1: SALIK | O1: SILJ | P1: STM | Q1: URNM | R1: VSH | S1: WOLF | T1: USD_AED
A2: 2025-07-07 | B2: 31.85 | C2: 45.33 | D2: 27.76 | E2: 2.68 | F2: 13.9 | G2: 27.8 | H2: 29 | I2: 69.02 | J2: 93.46 | K2: 1.75 | L2: 89.85 | M2: 153.37 | N2: 6.38 | O2: 15.39 | P2: 31.56 | Q2: 46.73 | R2: 16.64 | S2: 21.62 | T2: 3.673
A3: 2025-07-08 | B3: 33.13 | C3: 45.65 | D3: 27.76 | E3: 2.68 | F3: 13.9 | G3: 27.8 | H3: 29 | I3: 66.39 | J3: 91.27 | K3: 1.79 | L3: 86.87 | M3: 145.96 | N3: 6.38 | O3: 14.57 | P3: 32.52 | Q3: 45.22 | R3: 17.35 | S3: 21.62 | T3: 3.673175
A4: 2025-07-09 | B4: 33.32 | C4: 44.91 | D4: 27.76 | E4: 2.68 | F4: 13.9 | G4: 27.8 | H4: 29 | I4: 67.22 | J4: 94.54 | K4: 1.84 | L4: 91.59 | M4: 145.65 | N4: 6.38 | O4: 14.83 | P4: 31.97 | Q4: 44.44 | R4: 17.61 | S4: 21.62 | T4: 3.673175
A5: 2025-07-10 | B5: 34.74 | C5: 45.48 | D5: 27.76 | E5: 2.68 | F5: 13.9 | G5: 27.8 | H5: 29 | I5: 67.52 | J5: 98.7 | K5: 2.01 | L5: 86.14 | M5: 143 | N5: 6.38 | O5: 15.15 | P5: 33.14 | Q5: 45 | R5: 17.88 | S5: 21.62 | T5: 3.673075
A6: 2025-07-11 | B6: 34.34 | C6: 45.16 | D6: 27.76 | E6: 2.68 | F6: 13.9 | G6: 27.8 | H6: 29 | I6: 68.84 | J6: 98.34 | K6: 2.12 | L6: 84.54 | M6: 145.59 | N6: 6.38 | O6: 15.81 | P6: 32.27 | Q6: 45.67 | R6: 17.85 | S6: 21.62 | T6: 3.673075
A7: 2025-07-14 | B7: 33.78 | C7: 44.92 | D7: 27.76 | E7: 2.68 | F7: 13.9 | G7: 27.8 | H7: 29 | I7: 68.58 | J7: 99.96 | K7: 2.31 | L7: 85.84 | M7: 146.38 | N7: 6.38 | O7: 15.65 | P7: 31.79 | Q7: 46.95 | R7: 17.47 | S7: 21.62 | T7: 3.673025
A8: 2025-07-15 | B8: 33.22 | C8: 44.34 | D8: 27.76 | E8: 2.68 | F8: 13.9 | G8: 27.8 | H8: 29 | I8: 67.63 | J8: 99.54 | K8: 2.29 | L8: 87.34 | M8: 144.8 | N8: 6.38 | O8: 15.43 | P8: 31.52 | Q8: 47.54 | R8: 16.99 | S8: 21.62 | T8: 3.672975
A9: 2025-07-16 | B9: 33.32 | C9: 44.3 | D9: 27.76 | E9: 2.68 | F9: 13.9 | G9: 27.8 | H9: 29 | I9: 67.49 | J9: 103.25 | K9: 2.4 | L9: 87.49 | M9: 144.31 | N9: 6.38 | O9: 15.23 | P9: 31.87 | Q9: 48.56 | R9: 17.01 | S9: 21.62 | T9: 3.67305
A10: 2025-07-17 | B10: 33.81 | C10: 44.02 | D10: 27.76 | E10: 2.68 | F10: 13.9 | G10: 27.8 | H10: 29 | I10: 66.76 | J10: 105.45 | K10: 2.4 | L10: 86.93 | M10: 142.52 | N10: 6.38 | O10: 15.15 | P10: 32.11 | Q10: 49.14 | R10: 17.28 | S10: 21.62 | T10: 3.675525
A11: 2025-07-18 | B11: 34.07 | C11: 43.87 | D11: 27.76 | E11: 2.68 | F11: 13.9 | G11: 27.8 | H11: 29 | I11: 66.19 | J11: 109.74 | K11: 2.23 | L11: 88.11 | M11: 148.24 | N11: 6.38 | O11: 14.95 | P11: 32.55 | Q11: 49.18 | R11: 17.24 | S11: 21.62 | T11: 3.675525
A12: 2025-07-21 | B12: 33.73 | C12: 44.88 | D12: 27.76 | E12: 2.68 | F12: 13.9 | G12: 27.8 | H12: 29 | I12: 68.59 | J12: 104.34 | K12: 2.25 | L12: 86.53 | M12: 146.29 | N12: 6.38 | O12: 15.47 | P12: 32.81 | Q12: 49.01 | R12: 17.45 | S12: 21.62 | T12: 3.673
A13: 2025-07-22 | B13: 34.26 | C13: 46.1 | D13: 27.76 | E13: 2.68 | F13: 13.9 | G13: 27.8 | H13: 29 | I13: 70.28 | J13: 101.85 | K13: 2.1 | L13: 83.77 | M13: 145.8 | N13: 6.38 | O13: 15.89 | P13: 33.41 | Q13: 49.57 | R13: 17.52 | S13: 21.62 | T13: 3.673025
... A262: 2026-07-05 | B262: 67.8 | C262: 76.65 | D262: 60.63 | E262: 2.33 | F262: 12.12 | G262: 30.64 | H262: 46.86 | I262: 102.91 | J262: 112.73 | K262: 7.41 | L262: 83.64 | M262: 194.67 | N262: 5.94 | O262: 26.73 | P262: 68.35 | Q262: 52.83 | R262: 45.92 | S262: 40 | T262: 3.673075

Sheet Reference_Data
A1: Ticker | B1: Company | C1: Sector | D1: Industry | E1: Country | F1: Beta | G1: AvgCost | H1: Currency
A2: CGNX | B2: COGNEX CORP | C2: Information Technology | D2: Electronic Equipment & Instruments (Machine Vision) | E2: United States | F2: N/A | G2: 66.407183 | H2: USD
A3: COPX | B3: GLOBAL X COPPER MINERS ETF | C3: Materials (ETF) | D3: Copper Mining | E3: United States | F3: N/A | G3: 87.4567 | H3: USD
A4: DRAM | B4: ROUNDHILL MEMORY ETF | C4: Information Technology (ETF) | D4: Semiconductor Memory | E4: United States | F4: N/A | G4: 70.929958 | H4: USD
A5: DTC | B5: DUBAI TAXI CO PJSC | C5: Industrials | D5: Ground Transportation | E5: United Arab Emirates | F5: N/A | G5: 2.2257895 | H5: AED
A6: EMAAR | B6: EMAAR PROPERTIES PJSC | C6: Real Estate | D6: Real Estate Development | E6: United Arab Emirates | F6: N/A | G6: 12.1964 | H6: AED
A7: EMIRATESN | B7: EMIRATES NBD PJSC | C7: Financials | D7: Banks | E7: United Arab Emirates | F7: N/A | G7: 29.065 | H7: AED
A8: FPS | B8: FORGENT POWER SOLUTIONS-CL A | C8: Industrials | D8: Electrical Equipment | E8: United States | F8: N/A | G8: 58.010243 | H8: USD
A9: GDXJ | B9: VANECK JUNIOR GOLD MINERS | C9: Materials (ETF) | D9: Junior Gold Mining | E9: United States | F9: N/A | G9: 109.16006 | H9: USD
A10: HOOD | B10: ROBINHOOD MARKETS INC - A | C10: Financials | D10: Capital Markets / Brokerage | E10: United States | F10: N/A | G10: 104.209 | H10: USD
A11: ONDS | B11: ONDAS INC | C11: Information Technology | D11: Wireless Networking / Drones | E11: United States | F11: N/A | G11: 13.84638 | H11: USD
A12: RBRK | B12: RUBRIK INC-A | C12: Information Technology | D12: Software (Data Security) | E12: United States | F12: N/A | G12: 76.417043 | H12: USD
A13: RDDT | B13: REDDIT INC-CL A | C13: Communication Services | D13: Internet Content & Social Media | E13: United States | F13: N/A | G13: 188.58695 | H13: USD
... A19: WOLF | B19: WOLFSPEED INC | C19: Information Technology | D19: Semiconductors (SiC Power) | E19: United States | F19: N/A | G19: 59.74281 | H19: USD

Sheet Daily_Units
A1: Date | B1: ABXXF | C1: AEHR | D1: AKAM | E1: AMZN | F1: ARGT | G1: ARKK | H1: ASTS | I1: BABA | J1: BE | K1: BIDU | L1: BOIL | M1: BULL | N1: CF | O1: CGNX | P1: CLSK | Q1: COHR | R1: COPX | S1: CORN | T1: CPER | U1: CRM | V1: CRWV | W1: DDOG | X1: DFEN | Y1: DRAM | Z1: DTC | AA1: EMAAR | AB1: EMIRATESN | AC1: EWZ | AD1: FAZ | AE1: FPS | AF1: GDX | AG1: GDXJ | AH1: GLD | AI1: GLL | AJ1: HOOD | AK1: INR | AL1: INTC | AM1: IREN | AN1: IWM | AO1: LITE | AP1: LMT | AQ1: META | AR1: MP | AS1: MRVL | AT1: MSFT | AU1: NTR | AV1: NVTS | AW1: OKLO | AX1: ONDS | AY1: OXY | AZ1: PALL | BA1: PPLT | BB1: RBRK | BC1: RDDT | BD1: REMX | BE1: RKLB | BF1: RNMBY | BG1: RTX | BH1: SALIK | BI1: SBET | BJ1: SBIT | BK1: SEDG | BL1: SIL | BM1: SILJ | BN1: SLV | BO1: SOUN | BP1: SOXS | BQ1: SQQQ | BR1: STM | BS1: TLT | BT1: TSLZ | BU1: UGL | BV1: URA | BW1: URNM | BX1: USO | BY1: UVIX | BZ1: VG | CA1: VSH | CB1: WEAT | CC1: WOLF | CD1: ZROZ | CE1: ZSL
A2: 2025-07-07 | B2: 0 | C2: 0 | D2: 0 | E2: 1 | F2: 0 | G2: 0 | H2: 0 | I2: 0 | J2: 0 | K2: 0 | L2: 0 | M2: 0 | N2: 0 | O2: 0 | P2: 0 | Q2: 0 | R2: 10 | S2: 0 | T2: 0 | U2: 0 | V2: 0 | W2: 0 | X2: 0 | Y2: 0 | Z2: 0 | AA2: 0 | AB2: 0 | AC2: 0 | AD2: 0 | AE2: 0 | AF2: 3 | AG2: 0 | AH2: 0 | AI2: 0 | AJ2: 0 | AK2: 0 | AL2: 0 | AM2: 0 | AN2: 0 | AO2: 0 | AP2: 0 | AQ2: 0 | AR2: 0 | AS2: 0 | AT2: 0.5 | AU2: 0 | AV2: 0 | AW2: 0 | AX2: 0 | AY2: 0 | AZ2: 0 | BA2: 0 | BB2: 0 | BC2: 0 | BD2: 0 | BE2: 0 | BF2: 0 | BG2: 0 | BH2: 0 | BI2: 0 | BJ2: 0 | BK2: 0 | BL2: 4 | BM2: 0 | BN2: 0 | BO2: 0 | BP2: 0 | BQ2: 0 | BR2: 0 | BS2: 0 | BT2: 0 | BU2: 0 | BV2: 0 | BW2: 0 | BX2: 0 | BY2: 0 | BZ2: 0 | CA2: 0 | CB2: 0 | CC2: 0 | CD2: 0 | CE2: 0
A3: 2025-07-08 | B3: 0 | C3: 0 | D3: 0 | E3: 1 | F3: 0 | G3: 0 | H3: 0 | I3: 0 | J3: 0 | K3: 0 | L3: 0 | M3: 0 | N3: 0 | O3: 0 | P3: 0 | Q3: 0 | R3: 15 | S3: 0 | T3: 0 | U3: 0 | V3: 0 | W3: 0 | X3: 0 | Y3: 0 | Z3: 0 | AA3: 0 | AB3: 0 | AC3: 0 | AD3: 0 | AE3: 0 | AF3: 8 | AG3: 0 | AH3: 0 | AI3: 0 | AJ3: 0 | AK3: 0 | AL3: 0 | AM3: 0 | AN3: 0 | AO3: 0 | AP3: 0 | AQ3: 0 | AR3: 0 | AS3: 0 | AT3: 0.5 | AU3: 0 | AV3: 0 | AW3: 0 | AX3: 0 | AY3: 0 | AZ3: 0 | BA3: 0 | BB3: 0 | BC3: 0 | BD3: 0 | BE3: 0 | BF3: 0 | BG3: 0 | BH3: 0 | BI3: 3 | BJ3: 0 | BK3: 0 | BL3: 7 | BM3: 0 | BN3: 0 | BO3: 0 | BP3: 0 | BQ3: 0 | BR3: 0 | BS3: 0 | BT3: 0 | BU3: 0 | BV3: 0 | BW3: 0 | BX3: 0 | BY3: 0 | BZ3: 0 | CA3: 0 | CB3: 0 | CC3: 0 | CD3: 0 | CE3: 0
A4: 2025-07-09 | B4: 0 | C4: 0 | D4: 0 | E4: 1 | F4: 0 | G4: 0 | H4: 0 | I4: 0 | J4: 0 | K4: 0 | L4: 0 | M4: 0 | N4: 0 | O4: 0 | P4: 0 | Q4: 0 | R4: 15 | S4: 0 | T4: 0 | U4: 0 | V4: 0 | W4: 0 | X4: 0 | Y4: 0 | Z4: 0 | AA4: 0 | AB4: 0 | AC4: 0 | AD4: 0 | AE4: 0 | AF4: 8 | AG4: 0 | AH4: 0 | AI4: 0 | AJ4: 0 | AK4: 0 | AL4: 0 | AM4: 0 | AN4: 0 | AO4: 0 | AP4: 0 | AQ4: 0 | AR4: 0 | AS4: 0 | AT4: 0.5 | AU4: 0 | AV4: 0 | AW4: 0 | AX4: 0 | AY4: 0 | AZ4: 0 | BA4: 0 | BB4: 0 | BC4: 0 | BD4: 0 | BE4: 0 | BF4: 0 | BG4: 0 | BH4: 0 | BI4: 3 | BJ4: 0 | BK4: 0 | BL4: 7 | BM4: 0 | BN4: 0 | BO4: 0 | BP4: 0 | BQ4: 0 | BR4: 0 | BS4: 0 | BT4: 0 | BU4: 0 | BV4: 0 | BW4: 0 | BX4: 0 | BY4: 0 | BZ4: 0 | CA4: 0 | CB4: 0 | CC4: 0 | CD4: 0 | CE4: 0
A5: 2025-07-10 | B5: 0 | C5: 0 | D5: 0 | E5: 1 | F5: 0 | G5: 0 | H5: 0 | I5: 0 | J5: 0 | K5: 0 | L5: 0 | M5: 0 | N5: 0 | O5: 0 | P5: 0 | Q5: 0 | R5: 15 | S5: 0 | T5: 0 | U5: 0 | V5: 0 | W5: 0 | X5: 0 | Y5: 0 | Z5: 0 | AA5: 0 | AB5: 0 | AC5: 0 | AD5: 0 | AE5: 0 | AF5: 8 | AG5: 0 | AH5: 0 | AI5: 0 | AJ5: 0 | AK5: 0 | AL5: 0 | AM5: 0 | AN5: 0 | AO5: 0 | AP5: 0 | AQ5: 0 | AR5: 0 | AS5: 0 | AT5: 0.5 | AU5: 0 | AV5: 0 | AW5: 0 | AX5: 0 | AY5: 0 | AZ5: 0 | BA5: 0 | BB5: 0 | BC5: 0 | BD5: 0 | BE5: 0 | BF5: 0 | BG5: 0 | BH5: 0 | BI5: 3 | BJ5: 0 | BK5: 0 | BL5: 7 | BM5: 0 | BN5: 0 | BO5: 0 | BP5: 0 | BQ5: 0 | BR5: 0 | BS5: 0 | BT5: 0 | BU5: 0 | BV5: 0 | BW5: 0 | BX5: 0 | BY5: 0 | BZ5: 0 | CA5: 0 | CB5: 0 | CC5: 0 | CD5: 0 | CE5: 0
A6: 2025-07-11 | B6: 0 | C6: 0 | D6: 0 | E6: 1 | F6: 0 | G6: 0 | H6: 0 | I6: 0 | J6: 0 | K6: 0 | L6: 0 | M6: 0 | N6: 0 | O6: 0 | P6: 0 | Q6: 0 | R6: 15 | S6: 0 | T6: 0 | U6: 0 | V6: 0 | W6: 0 | X6: 0 | Y6: 0 | Z6: 0 | AA6: 0 | AB6: 0 | AC6: 0 | AD6: 0 | AE6: 0 | AF6: 8 | AG6: 0 | AH6: 0 | AI6: 0 | AJ6: 0 | AK6: 0 | AL6: 0 | AM6: 0 | AN6: 0 | AO6: 0 | AP6: 0 | AQ6: 0 | AR6: 0 | AS6: 0 | AT6: 0.5 | AU6: 0 | AV6: 0 | AW6: 0 | AX6: 0 | AY6: 0 | AZ6: 0 | BA6: 0 | BB6: 0 | BC6: 0 | BD6: 0 | BE6: 0 | BF6: 0 | BG6: 0 | BH6: 0 | BI6: 0 | BJ6: 0 | BK6: 0 | BL6: 7 | BM6: 0 | BN6: 0 | BO6: 0 | BP6: 0 | BQ6: 0 | BR6: 0 | BS6: 0 | BT6: 0 | BU6: 0 | BV6: 0 | BW6: 0 | BX6: 0 | BY6: 0 | BZ6: 0 | CA6: 0 | CB6: 0 | CC6: 0 | CD6: 0 | CE6: 0
A7: 2025-07-14 | B7: 0 | C7: 0 | D7: 0 | E7: 1 | F7: 3 | G7: 0 | H7: 0 | I7: 0 | J7: 0 | K7: 0 | L7: 0 | M7: 0 | N7: 0 | O7: 0 | P7: 6 | Q7: 0 | R7: 15 | S7: 0 | T7: 0 | U7: 0 | V7: 0 | W7: 0 | X7: 0 | Y7: 0 | Z7: 0 | AA7: 0 | AB7: 0 | AC7: 0 | AD7: 0 | AE7: 0 | AF7: 8 | AG7: 0 | AH7: 0 | AI7: 0 | AJ7: 0 | AK7: 0 | AL7: 0 | AM7: 7 | AN7: 0 | AO7: 0 | AP7: 0 | AQ7: 0 | AR7: 0 | AS7: 0 | AT7: 0.5 | AU7: 0 | AV7: 0 | AW7: 2 | AX7: 0 | AY7: 0 | AZ7: 0 | BA7: 0 | BB7: 0 | BC7: 0 | BD7: 0 | BE7: 0 | BF7: 0 | BG7: 0 | BH7: 0 | BI7: 0 | BJ7: 0 | BK7: 0 | BL7: 7 | BM7: 0 | BN7: 0 | BO7: 0 | BP7: 0 | BQ7: 0 | BR7: 0 | BS7: 0 | BT7: 0 | BU7: 0 | BV7: 0 | BW7: 0 | BX7: 0 | BY7: 0 | BZ7: 0 | CA7: 0 | CB7: 0 | CC7: 0 | CD7: 0 | CE7: 0
A8: 2025-07-15 | B8: 0 | C8: 0 | D8: 0 | E8: 1 | F8: 3 | G8: 0 | H8: 0 | I8: 0 | J8: 0 | K8: 0 | L8: 0 | M8: 0 | N8: 0 | O8: 0 | P8: 6 | Q8: 0 | R8: 15 | S8: 0 | T8: 0 | U8: 0 | V8: 0 | W8: 0 | X8: 0 | Y8: 0 | Z8: 0 | AA8: 0 | AB8: 0 | AC8: 0 | AD8: 0 | AE8: 0 | AF8: 8 | AG8: 0 | AH8: 0 | AI8: 0 | AJ8: 0 | AK8: 0 | AL8: 0 | AM8: 7 | AN8: 0 | AO8: 0 | AP8: 0 | AQ8: 0 | AR8: 0 | AS8: 0 | AT8: 0.5 | AU8: 0 | AV8: 0 | AW8: 2 | AX8: 0 | AY8: 0 | AZ8: 0 | BA8: 0 | BB8: 0 | BC8: 0 | BD8: 0 | BE8: 0 | BF8: 0 | BG8: 0 | BH8: 0 | BI8: 0 | BJ8: 0 | BK8: 0 | BL8: 7 | BM8: 0 | BN8: 0 | BO8: 0 | BP8: 0 | BQ8: 0 | BR8: 0 | BS8: 0 | BT8: 0 | BU8: 0 | BV8: 0 | BW8: 0 | BX8: 0 | BY8: 0 | BZ8: 0 | CA8: 0 | CB8: 0 | CC8: 0 | CD8: 0 | CE8: 0
A9: 2025-07-16 | B9: 0 | C9: 0 | D9: 0 | E9: 1 | F9: 3 | G9: 0 | H9: 0 | I9: 0 | J9: 0 | K9: 0 | L9: 0 | M9: 0 | N9: 0 | O9: 0 | P9: 6 | Q9: 0 | R9: 15 | S9: 0 | T9: 0 | U9: 0 | V9: 0 | W9: 0 | X9: 0 | Y9: 0 | Z9: 0 | AA9: 0 | AB9: 0 | AC9: 0 | AD9: 0 | AE9: 0 | AF9: 8 | AG9: 0 | AH9: 0 | AI9: 0 | AJ9: 0 | AK9: 0 | AL9: 0 | AM9: 7 | AN9: 0 | AO9: 0 | AP9: 0 | AQ9: 0 | AR9: 0 | AS9: 0 | AT9: 0.5 | AU9: 0 | AV9: 0 | AW9: 2 | AX9: 0 | AY9: 0 | AZ9: 0 | BA9: 0 | BB9: 0 | BC9: 0 | BD9: 0 | BE9: 0 | BF9: 0 | BG9: 0 | BH9: 0 | BI9: 0 | BJ9: 0 | BK9: 0 | BL9: 11 | BM9: 0 | BN9: 0 | BO9: 0 | BP9: 0 | BQ9: 0 | BR9: 0 | BS9: 0 | BT9: 0 | BU9: 0 | BV9: 0 | BW9: 0 | BX9: 0 | BY9: 0 | BZ9: 0 | CA9: 0 | CB9: 0 | CC9: 0 | CD9: 0 | CE9: 0
A10: 2025-07-17 | B10: 0 | C10: 0 | D10: 0 | E10: 1 | F10: 3 | G10: 0 | H10: 0 | I10: 0 | J10: 0 | K10: 0 | L10: 0 | M10: 0 | N10: 0 | O10: 0 | P10: 6 | Q10: 0 | R10: 15 | S10: 0 | T10: 0 | U10: 0 | V10: 0 | W10: 0 | X10: 0 | Y10: 0 | Z10: 0 | AA10: 0 | AB10: 0 | AC10: 0 | AD10: 0 | AE10: 0 | AF10: 8 | AG10: 0 | AH10: 0 | AI10: 0 | AJ10: 0 | AK10: 0 | AL10: 0 | AM10: 7 | AN10: 0 | AO10: 0 | AP10: 0 | AQ10: 0 | AR10: 0 | AS10: 0 | AT10: 0.5 | AU10: 0 | AV10: 0 | AW10: 2 | AX10: 0 | AY10: 0 | AZ10: 0 | BA10: 0 | BB10: 0 | BC10: 0 | BD10: 0 | BE10: 0 | BF10: 0 | BG10: 0 | BH10: 0 | BI10: 0 | BJ10: 0 | BK10: 0 | BL10: 11 | BM10: 0 | BN10: 0 | BO10: 0 | BP10: 0 | BQ10: 0 | BR10: 0 | BS10: 0 | BT10: 0 | BU10: 0 | BV10: 0 | BW10: 0 | BX10: 0 | BY10: 0 | BZ10: 0 | CA10: 0 | CB10: 0 | CC10: 0 | CD10: 0 | CE10: 0
A11: 2025-07-18 | B11: 0 | C11: 0 | D11: 0 | E11: 1 | F11: 3 | G11: 0 | H11: 0 | I11: 0 | J11: 0 | K11: 0 | L11: 0 | M11: 0 | N11: 0 | O11: 0 | P11: 6 | Q11: 0 | R11: 15 | S11: 0 | T11: 0 | U11: 0 | V11: 0 | W11: 0 | X11: 0 | Y11: 0 | Z11: 0 | AA11: 0 | AB11: 0 | AC11: 0 | AD11: 0 | AE11: 0 | AF11: 8 | AG11: 0 | AH11: 0 | AI11: 0 | AJ11: 0 | AK11: 0 | AL11: 0 | AM11: 7 | AN11: 0 | AO11: 0 | AP11: 0 | AQ11: 0 | AR11: 0 | AS11: 0 | AT11: 0.5 | AU11: 0 | AV11: 0 | AW11: 2 | AX11: 0 | AY11: 0 | AZ11: 0 | BA11: 0 | BB11: 0 | BC11: 0 | BD11: 0 | BE11: 0 | BF11: 0 | BG11: 0 | BH11: 0 | BI11: 0 | BJ11: 0 | BK11: 0 | BL11: 11 | BM11: 0 | BN11: 0 | BO11: 0 | BP11: 0 | BQ11: 0 | BR11: 0 | BS11: 0 | BT11: 0 | BU11: 0 | BV11: 0 | BW11: 0 | BX11: 0 | BY11: 0 | BZ11: 0 | CA11: 0 | CB11: 0 | CC11: 0 | CD11: 0 | CE11: 0
A12: 2025-07-21 | B12: 0 | C12: 0 | D12: 0 | E12: 1 | F12: 3 | G12: 0 | H12: 0 | I12: 0 | J12: 0 | K12: 0 | L12: 0 | M12: 0 | N12: 0 | O12: 0 | P12: 6 | Q12: 0 | R12: 15 | S12: 0 | T12: 0 | U12: 0 | V12: 0 | W12: 0 | X12: 0 | Y12: 0 | Z12: 0 | AA12: 0 | AB12: 0 | AC12: 0 | AD12: 0 | AE12: 0 | AF12: 8 | AG12: 0 | AH12: 0 | AI12: 0 | AJ12: 0 | AK12: 0 | AL12: 0 | AM12: 7 | AN12: 0 | AO12: 0 | AP12: 0 | AQ12: 0 | AR12: 0 | AS12: 0 | AT12: 0.5 | AU12: 0 | AV12: 0 | AW12: 2 | AX12: 0 | AY12: 0 | AZ12: 0 | BA12: 0 | BB12: 0 | BC12: 0 | BD12: 0 | BE12: 0 | BF12: 0 | BG12: 0 | BH12: 0 | BI12: 0 | BJ12: 0 | BK12: 0 | BL12: 11 | BM12: 0 | BN12: 0 | BO12: 0 | BP12: 0 | BQ12: 0 | BR12: 0 | BS12: 0 | BT12: 0 | BU12: 0 | BV12: 0 | BW12: 0 | BX12: 0 | BY12: 0 | BZ12: 0 | CA12: 0 | CB12: 0 | CC12: 0 | CD12: 0 | CE12: 0
A13: 2025-07-22 | B13: 0 | C13: 0 | D13: 0 | E13: 1 | F13: 3 | G13: 0 | H13: 0 | I13: 0 | J13: 0 | K13: 2 | L13: 0 | M13: 0 | N13: 0 | O13: 0 | P13: 6 | Q13: 0 | R13: 15 | S13: 0 | T13: 0 | U13: 0 | V13: 0 | W13: 0 | X13: 0 | Y13: 0 | Z13: 0 | AA13: 0 | AB13: 0 | AC13: 0 | AD13: 0 | AE13: 0 | AF13: 8 | AG13: 0 | AH13: 0 | AI13: 0 | AJ13: 0 | AK13: 0 | AL13: 0 | AM13: 7 | AN13: 0 | AO13: 0 | AP13: 0 | AQ13: 0 | AR13: 0 | AS13: 0 | AT13: 0.5 | AU13: 0 | AV13: 0 | AW13: 2 | AX13: 0 | AY13: 0 | AZ13: 0 | BA13: 0 | BB13: 0 | BC13: 0 | BD13: 0 | BE13: 0 | BF13: 0 | BG13: 0 | BH13: 0 | BI13: 0 | BJ13: 0 | BK13: 0 | BL13: 11 | BM13: 0 | BN13: 0 | BO13: 0 | BP13: 0 | BQ13: 0 | BR13: 0 | BS13: 0 | BT13: 0 | BU13: 0 | BV13: 0 | BW13: 0 | BX13: 0 | BY13: 0 | BZ13: 0 | CA13: 0 | CB13: 0 | CC13: 0 | CD13: 0 | CE13: 0
... A262: 2026-07-05 | B262: 0 | C262: 0 | D262: 0 | E262: 0 | F262: 0 | G262: 0 | H262: 0 | I262: 0 | J262: 0 | K262: 0 | L262: 0 | M262: 0 | N262: 0 | O262: 6 | P262: 0 | Q262: 0 | R262: 4 | S262: 0 | T262: 0 | U262: 0 | V262: 0 | W262: 0 | X262: 0 | Y262: 12 | Z262: 950 | AA262: 300 | AB262: 120 | AC262: 0 | AD262: 0 | AE262: 7 | AF262: 0 | AG262: 5 | AH262: 0 | AI262: 0 | AJ262: 10 | AK262: 0 | AL262: 0 | AM262: 0 | AN262: 0 | AO262: 0 | AP262: 0 | AQ262: 0 | AR262: 0 | AS262: 0 | AT262: 0 | AU262: 0 | AV262: 0 | AW262: 0 | AX262: 20 | AY262: 0 | AZ262: 0 | BA262: 0 | BB262: 7 | BC262: 6 | BD262: 0 | BE262: 0 | BF262: 0 | BG262: 0 | BH262: 400 | BI262: 0 | BJ262: 0 | BK262: 0 | BL262: 0 | BM262: 20 | BN262: 0 | BO262: 0 | BP262: 0 | BQ262: 0 | BR262: 8 | BS262: 0 | BT262: 0 | BU262: 0 | BV262: 0 | BW262: 10 | BX262: 0 | BY262: 0 | BZ262: 0 | CA262: 18 | CB262: 0 | CC262: 10 | CD262: 0 | CE262: 0

Sheet Daily_Cash
A1: Date | B1: NAV | C1: InvestedValue_Estimate | D1: Cash
A2: 2025-07-07 | B2: 3286.3495 | C2: 453.3 | D2: 2833.0495
A3: 2025-07-08 | B3: 3270.3848 | C3: 1468.005 | D3: 1802.3798
A4: 2025-07-09 | B4: 3278.1048 | C4: 1456.905 | D4: 1821.1998
A5: 2025-07-10 | B5: 3298.7648 | C5: 1465.455 | D5: 1833.3098
A6: 2025-07-11 | B6: 3321.4684 | C6: 1413.495 | D6: 1907.9734
A7: 2025-07-14 | B7: 3310.6398 | C7: 1975.3987 | D7: 1335.2411
A8: 2025-07-15 | B8: 3286.5998 | C8: 1966.6987 | D8: 1319.9011
A9: 2025-07-16 | B9: 3290.5687 | C9: 2170.4737 | D9: 1120.095
A10: 2025-07-17 | B10: 3295.5587 | C10: 2166.2737 | D10: 1129.285
A11: 2025-07-18 | B11: 3289.8987 | C11: 2164.0237 | D11: 1125.875
A12: 2025-07-21 | B12: 3327.9287 | C12: 2179.1737 | D12: 1148.755
A13: 2025-07-22 | B13: 3371.1806 | C13: 2382.7537 | D13: 988.42689
... A262: 2026-07-05 | B262: 12864.881 | C262: 11389.208 | D262: 1475.6729

Sheet Positions
A1: Ticker | B1: Company | C1: Sector | D1: Currency | E1: Shares | F1: Avg Cost | G1: Current Price | H1: Day Change % | I1: Cost Basis ($) | J1: Market Value ($) | K1: Unrealized P&L ($) | L1: P&L % | M1: Portfolio Weight
A2: ='Reference_Data'!A2 | B2: ='Reference_Data'!B2 | C2: ='Reference_Data'!C2 | D2: ='Reference_Data'!H2 | E2: ='Daily_Units'!O$262 | F2: ='Reference_Data'!G2 | G2: ='Market_Data'!B$262 | H2: =('Market_Data'!B$262-'Market_Data'!B$261)/'Market_Data'!B$261 | I2: =E2*F2 | J2: =E2*G2 | K2: =J2-I2 | L2: =IFERROR(K2/I2,0) | M2: =J2/SUM($J$2:$J$19)
A3: ='Reference_Data'!A3 | B3: ='Reference_Data'!B3 | C3: ='Reference_Data'!C3 | D3: ='Reference_Data'!H3 | E3: ='Daily_Units'!R$262 | F3: ='Reference_Data'!G3 | G3: ='Market_Data'!C$262 | H3: =('Market_Data'!C$262-'Market_Data'!C$261)/'Market_Data'!C$261 | I3: =E3*F3 | J3: =E3*G3 | K3: =J3-I3 | L3: =IFERROR(K3/I3,0) | M3: =J3/SUM($J$2:$J$19)
A4: ='Reference_Data'!A4 | B4: ='Reference_Data'!B4 | C4: ='Reference_Data'!C4 | D4: ='Reference_Data'!H4 | E4: ='Daily_Units'!Y$262 | F4: ='Reference_Data'!G4 | G4: ='Market_Data'!D$262 | H4: =('Market_Data'!D$262-'Market_Data'!D$261)/'Market_Data'!D$261 | I4: =E4*F4 | J4: =E4*G4 | K4: =J4-I4 | L4: =IFERROR(K4/I4,0) | M4: =J4/SUM($J$2:$J$19)
A5: ='Reference_Data'!A5 | B5: ='Reference_Data'!B5 | C5: ='Reference_Data'!C5 | D5: ='Reference_Data'!H5 | E5: ='Daily_Units'!Z$262 | F5: ='Reference_Data'!G5 | G5: ='Market_Data'!E$262 | H5: =('Market_Data'!E$262-'Market_Data'!E$261)/'Market_Data'!E$261 | I5: =E5*F5/'Market_Data'!$T$262 | J5: =E5*G5/'Market_Data'!$T$262 | K5: =J5-I5 | L5: =IFERROR(K5/I5,0) | M5: =J5/SUM($J$2:$J$19)
A6: ='Reference_Data'!A6 | B6: ='Reference_Data'!B6 | C6: ='Reference_Data'!C6 | D6: ='Reference_Data'!H6 | E6: ='Daily_Units'!AA$262 | F6: ='Reference_Data'!G6 | G6: ='Market_Data'!F$262 | H6: =('Market_Data'!F$262-'Market_Data'!F$261)/'Market_Data'!F$261 | I6: =E6*F6/'Market_Data'!$T$262 | J6: =E6*G6/'Market_Data'!$T$262 | K6: =J6-I6 | L6: =IFERROR(K6/I6,0) | M6: =J6/SUM($J$2:$J$19)
A7: ='Reference_Data'!A7 | B7: ='Reference_Data'!B7 | C7: ='Reference_Data'!C7 | D7: ='Reference_Data'!H7 | E7: ='Daily_Units'!AB$262 | F7: ='Reference_Data'!G7 | G7: ='Market_Data'!G$262 | H7: =('Market_Data'!G$262-'Market_Data'!G$261)/'Market_Data'!G$261 | I7: =E7*F7/'Market_Data'!$T$262 | J7: =E7*G7/'Market_Data'!$T$262 | K7: =J7-I7 | L7: =IFERROR(K7/I7,0) | M7: =J7/SUM($J$2:$J$19)
A8: ='Reference_Data'!A8 | B8: ='Reference_Data'!B8 | C8: ='Reference_Data'!C8 | D8: ='Reference_Data'!H8 | E8: ='Daily_Units'!AE$262 | F8: ='Reference_Data'!G8 | G8: ='Market_Data'!H$262 | H8: =('Market_Data'!H$262-'Market_Data'!H$261)/'Market_Data'!H$261 | I8: =E8*F8 | J8: =E8*G8 | K8: =J8-I8 | L8: =IFERROR(K8/I8,0) | M8: =J8/SUM($J$2:$J$19)
A9: ='Reference_Data'!A9 | B9: ='Reference_Data'!B9 | C9: ='Reference_Data'!C9 | D9: ='Reference_Data'!H9 | E9: ='Daily_Units'!AG$262 | F9: ='Reference_Data'!G9 | G9: ='Market_Data'!I$262 | H9: =('Market_Data'!I$262-'Market_Data'!I$261)/'Market_Data'!I$261 | I9: =E9*F9 | J9: =E9*G9 | K9: =J9-I9 | L9: =IFERROR(K9/I9,0) | M9: =J9/SUM($J$2:$J$19)
A10: ='Reference_Data'!A10 | B10: ='Reference_Data'!B10 | C10: ='Reference_Data'!C10 | D10: ='Reference_Data'!H10 | E10: ='Daily_Units'!AJ$262 | F10: ='Reference_Data'!G10 | G10: ='Market_Data'!J$262 | H10: =('Market_Data'!J$262-'Market_Data'!J$261)/'Market_Data'!J$261 | I10: =E10*F10 | J10: =E10*G10 | K10: =J10-I10 | L10: =IFERROR(K10/I10,0) | M10: =J10/SUM($J$2:$J$19)
A11: ='Reference_Data'!A11 | B11: ='Reference_Data'!B11 | C11: ='Reference_Data'!C11 | D11: ='Reference_Data'!H11 | E11: ='Daily_Units'!AX$262 | F11: ='Reference_Data'!G11 | G11: ='Market_Data'!K$262 | H11: =('Market_Data'!K$262-'Market_Data'!K$261)/'Market_Data'!K$261 | I11: =E11*F11 | J11: =E11*G11 | K11: =J11-I11 | L11: =IFERROR(K11/I11,0) | M11: =J11/SUM($J$2:$J$19)
A12: ='Reference_Data'!A12 | B12: ='Reference_Data'!B12 | C12: ='Reference_Data'!C12 | D12: ='Reference_Data'!H12 | E12: ='Daily_Units'!BB$262 | F12: ='Reference_Data'!G12 | G12: ='Market_Data'!L$262 | H12: =('Market_Data'!L$262-'Market_Data'!L$261)/'Market_Data'!L$261 | I12: =E12*F12 | J12: =E12*G12 | K12: =J12-I12 | L12: =IFERROR(K12/I12,0) | M12: =J12/SUM($J$2:$J$19)
A13: ='Reference_Data'!A13 | B13: ='Reference_Data'!B13 | C13: ='Reference_Data'!C13 | D13: ='Reference_Data'!H13 | E13: ='Daily_Units'!BC$262 | F13: ='Reference_Data'!G13 | G13: ='Market_Data'!M$262 | H13: =('Market_Data'!M$262-'Market_Data'!M$261)/'Market_Data'!M$261 | I13: =E13*F13 | J13: =E13*G13 | K13: =J13-I13 | L13: =IFERROR(K13/I13,0) | M13: =J13/SUM($J$2:$J$19)
A14: ='Reference_Data'!A14 | B14: ='Reference_Data'!B14 | C14: ='Reference_Data'!C14 | D14: ='Reference_Data'!H14 | E14: ='Daily_Units'!BH$262 | F14: ='Reference_Data'!G14 | G14: ='Market_Data'!N$262 | H14: =('Market_Data'!N$262-'Market_Data'!N$261)/'Market_Data'!N$261 | I14: =E14*F14/'Market_Data'!$T$262 | J14: =E14*G14/'Market_Data'!$T$262 | K14: =J14-I14 | L14: =IFERROR(K14/I14,0) | M14: =J14/SUM($J$2:$J$19)
A15: ='Reference_Data'!A15 | B15: ='Reference_Data'!B15 | C15: ='Reference_Data'!C15 | D15: ='Reference_Data'!H15 | E15: ='Daily_Units'!BM$262 | F15: ='Reference_Data'!G15 | G15: ='Market_Data'!O$262 | H15: =('Market_Data'!O$262-'Market_Data'!O$261)/'Market_Data'!O$261 | I15: =E15*F15 | J15: =E15*G15 | K15: =J15-I15 | L15: =IFERROR(K15/I15,0) | M15: =J15/SUM($J$2:$J$19)
A16: ='Reference_Data'!A16 | B16: ='Reference_Data'!B16 | C16: ='Reference_Data'!C16 | D16: ='Reference_Data'!H16 | E16: ='Daily_Units'!BR$262 | F16: ='Reference_Data'!G16 | G16: ='Market_Data'!P$262 | H16: =('Market_Data'!P$262-'Market_Data'!P$261)/'Market_Data'!P$261 | I16: =E16*F16 | J16: =E16*G16 | K16: =J16-I16 | L16: =IFERROR(K16/I16,0) | M16: =J16/SUM($J$2:$J$19)
A17: ='Reference_Data'!A17 | B17: ='Reference_Data'!B17 | C17: ='Reference_Data'!C17 | D17: ='Reference_Data'!H17 | E17: ='Daily_Units'!BW$262 | F17: ='Reference_Data'!G17 | G17: ='Market_Data'!Q$262 | H17: =('Market_Data'!Q$262-'Market_Data'!Q$261)/'Market_Data'!Q$261 | I17: =E17*F17 | J17: =E17*G17 | K17: =J17-I17 | L17: =IFERROR(K17/I17,0) | M17: =J17/SUM($J$2:$J$19)
A18: ='Reference_Data'!A18 | B18: ='Reference_Data'!B18 | C18: ='Reference_Data'!C18 | D18: ='Reference_Data'!H18 | E18: ='Daily_Units'!CA$262 | F18: ='Reference_Data'!G18 | G18: ='Market_Data'!R$262 | H18: =('Market_Data'!R$262-'Market_Data'!R$261)/'Market_Data'!R$261 | I18: =E18*F18 | J18: =E18*G18 | K18: =J18-I18 | L18: =IFERROR(K18/I18,0) | M18: =J18/SUM($J$2:$J$19)
A19: ='Reference_Data'!A19 | B19: ='Reference_Data'!B19 | C19: ='Reference_Data'!C19 | D19: ='Reference_Data'!H19 | E19: ='Daily_Units'!CC$262 | F19: ='Reference_Data'!G19 | G19: ='Market_Data'!S$262 | H19: =('Market_Data'!S$262-'Market_Data'!S$261)/'Market_Data'!S$261 | I19: =E19*F19 | J19: =E19*G19 | K19: =J19-I19 | L19: =IFERROR(K19/I19,0) | M19: =J19/SUM($J$2:$J$19)

Sheet Equity_Curve
A1: Date | B1: Cash ($) | C1: Invested Value ($) | D1: Total NAV ($) | E1: Daily Return | F1: Cumulative Return | G1: Drawdown
A2: ='Daily_Cash'!A2 | B2: ='Daily_Cash'!D2 | C2: =D2-B2 | D2: ='Daily_Cash'!B2 | E2: 0 | F2: =D2/D$2-1 | G2: =D2/MAX(D$2:D2)-1
A3: ='Daily_Cash'!A3 | B3: ='Daily_Cash'!D3 | C3: =D3-B3 | D3: ='Daily_Cash'!B3 | E3: =D3/D2-1 | F3: =D3/D$2-1 | G3: =D3/MAX(D$2:D3)-1
A4: ='Daily_Cash'!A4 | B4: ='Daily_Cash'!D4 | C4: =D4-B4 | D4: ='Daily_Cash'!B4 | E4: =D4/D3-1 | F4: =D4/D$2-1 | G4: =D4/MAX(D$2:D4)-1
A5: ='Daily_Cash'!A5 | B5: ='Daily_Cash'!D5 | C5: =D5-B5 | D5: ='Daily_Cash'!B5 | E5: =D5/D4-1 | F5: =D5/D$2-1 | G5: =D5/MAX(D$2:D5)-1
A6: ='Daily_Cash'!A6 | B6: ='Daily_Cash'!D6 | C6: =D6-B6 | D6: ='Daily_Cash'!B6 | E6: =D6/D5-1 | F6: =D6/D$2-1 | G6: =D6/MAX(D$2:D6)-1
A7: ='Daily_Cash'!A7 | B7: ='Daily_Cash'!D7 | C7: =D7-B7 | D7: ='Daily_Cash'!B7 | E7: =D7/D6-1 | F7: =D7/D$2-1 | G7: =D7/MAX(D$2:D7)-1
A8: ='Daily_Cash'!A8 | B8: ='Daily_Cash'!D8 | C8: =D8-B8 | D8: ='Daily_Cash'!B8 | E8: =D8/D7-1 | F8: =D8/D$2-1 | G8: =D8/MAX(D$2:D8)-1
A9: ='Daily_Cash'!A9 | B9: ='Daily_Cash'!D9 | C9: =D9-B9 | D9: ='Daily_Cash'!B9 | E9: =D9/D8-1 | F9: =D9/D$2-1 | G9: =D9/MAX(D$2:D9)-1
A10: ='Daily_Cash'!A10 | B10: ='Daily_Cash'!D10 | C10: =D10-B10 | D10: ='Daily_Cash'!B10 | E10: =D10/D9-1 | F10: =D10/D$2-1 | G10: =D10/MAX(D$2:D10)-1
A11: ='Daily_Cash'!A11 | B11: ='Daily_Cash'!D11 | C11: =D11-B11 | D11: ='Daily_Cash'!B11 | E11: =D11/D10-1 | F11: =D11/D$2-1 | G11: =D11/MAX(D$2:D11)-1
A12: ='Daily_Cash'!A12 | B12: ='Daily_Cash'!D12 | C12: =D12-B12 | D12: ='Daily_Cash'!B12 | E12: =D12/D11-1 | F12: =D12/D$2-1 | G12: =D12/MAX(D$2:D12)-1
A13: ='Daily_Cash'!A13 | B13: ='Daily_Cash'!D13 | C13: =D13-B13 | D13: ='Daily_Cash'!B13 | E13: =D13/D12-1 | F13: =D13/D$2-1 | G13: =D13/MAX(D$2:D13)-1
A14: ='Daily_Cash'!A14 | B14: ='Daily_Cash'!D14 | C14: =D14-B14 | D14: ='Daily_Cash'!B14 | E14: =D14/D13-1 | F14: =D14/D$2-1 | G14: =D14/MAX(D$2:D14)-1
... A262: ='Daily_Cash'!A262 | B262: ='Daily_Cash'!D262 | C262: =D262-B262 | D262: ='Daily_Cash'!B262 | E262: =D262/D261-1 | F262: =D262/D$2-1 | G262: =D262/MAX(D$2:D262)-1

Sheet Sector_Exposure
A1: Sector | B1: Market Value ($) | C1: Weight
A2: Communication Services | B2: =SUMIF(Positions!$C$2:$C$19,A2,Positions!$J$2:$J$19) | C2: =B2/SUM($B$2:$B$9)
A3: Energy / Materials (ETF) | B3: =SUMIF(Positions!$C$2:$C$19,A3,Positions!$J$2:$J$19) | C3: =B3/SUM($B$2:$B$9)
A4: Financials | B4: =SUMIF(Positions!$C$2:$C$19,A4,Positions!$J$2:$J$19) | C4: =B4/SUM($B$2:$B$9)
A5: Industrials | B5: =SUMIF(Positions!$C$2:$C$19,A5,Positions!$J$2:$J$19) | C5: =B5/SUM($B$2:$B$9)
A6: Information Technology | B6: =SUMIF(Positions!$C$2:$C$19,A6,Positions!$J$2:$J$19) | C6: =B6/SUM($B$2:$B$9)
A7: Information Technology (ETF) | B7: =SUMIF(Positions!$C$2:$C$19,A7,Positions!$J$2:$J$19) | C7: =B7/SUM($B$2:$B$9)
A8: Materials (ETF) | B8: =SUMIF(Positions!$C$2:$C$19,A8,Positions!$J$2:$J$19) | C8: =B8/SUM($B$2:$B$9)
A9: Real Estate | B9: =SUMIF(Positions!$C$2:$C$19,A9,Positions!$J$2:$J$19) | C9: =B9/SUM($B$2:$B$9)

Sheet Geographic_Exposure
A1: Country | B1: Market Value ($) | C1: Weight
A2: Canada (ETF Domicile) | B2: =SUMPRODUCT(('Reference_Data'!$E$2:$E$19=A2)*Positions!$J$2:$J$19) | C2: =B2/SUM($B$2:$B$5)
A3: Netherlands / Switzerland | B3: =SUMPRODUCT(('Reference_Data'!$E$2:$E$19=A3)*Positions!$J$2:$J$19) | C3: =B3/SUM($B$2:$B$5)
A4: United Arab Emirates | B4: =SUMPRODUCT(('Reference_Data'!$E$2:$E$19=A4)*Positions!$J$2:$J$19) | C4: =B4/SUM($B$2:$B$5)
A5: United States | B5: =SUMPRODUCT(('Reference_Data'!$E$2:$E$19=A5)*Positions!$J$2:$J$19) | C5: =B5/SUM($B$2:$B$5)
